<?xml version="1.0"?>
<robot xmlns:xacro="http://www.ros.org/wiki/xacro">
    <xacro:macro name="kelo_drive" params="name parent *origin">
        
        <xacro:include filename="$(find skratch_description)/description/wheels/kelo_drive_wheel.xacro"/>

        <link name="${name}_pivot_link">
            <visual>
                <origin xyz="0 0 0" rpy="0 0 0"/>
                <geometry>
                    <mesh filename="file://$(find skratch_description)/meshes/wheels/kelo_drive_mid_part.dae" scale="1 1 1"/>
                </geometry>
                <material name="black">
                    <color rgba="0.0 0.0 0.0 1.0"/>
                </material>
            </visual>

            <collision>
                <origin xyz="0 0 0" rpy="0 0 0"/>
                <geometry>
                    <mesh filename="file://$(find skratch_description)/meshes/wheels/kelo_drive_mid_part.dae" scale="1 1 1"/>
                </geometry>
            </collision>

            <inertial>
                <origin xyz="0.00023 -0.00095 0.04843" rpy="0 0 0"/>
                <mass value="1.46273"/>
                <inertia ixx="0.00302046423" ixy="0.00000851844" ixz="0.00001188180" iyy="0.00326495472" iyz="0.00001855408" izz="0.00386072964"/>
            </inertial>

        </link> 

        <joint name="${name}_pivot_joint" type="continuous">
            <xacro:insert_block name="origin" />
            <axis xyz="0 0 1"/>
            <parent link="${parent}"/>
            <child link="${name}_pivot_link" />
            <dynamics damping="0.1" friction="0.05"/>
            <limit effort="2.0" velocity="1.0"/>
        </joint>

    
        <!-- LEFT HUB WHEEL -->
        <xacro:kelo_drive_wheel name="${name}_left_hub_wheel" parent="${name}_pivot_link">
            <origin xyz="-0.0 0.039326 0.001514" rpy="0 0 0.0"/>
        </xacro:kelo_drive_wheel>

        <!-- RIGHT HUB WHEEL -->
        <xacro:kelo_drive_wheel name="${name}_right_hub_wheel" parent="${name}_pivot_link">
            <origin xyz="-0.0 -0.039326 0.001514" rpy="0 0 0.0"/>
        </xacro:kelo_drive_wheel>

    </xacro:macro>  
</robot>