<?xml version="1.0"?>
<robot xmlns:xacro="http://www.ros.org/wiki/xacro">
    <xacro:macro name="kelo_drive_wheel" params="name parent *origin">
        <link name="${name}_link">
            <visual>
                <origin xyz="0 0 0" rpy="0 0 0"/>
                <geometry>
                    <mesh filename="file://$(find skratch_description)/meshes/wheels/kelo_drive_wheel.stl" scale="1 1 1"/>
                </geometry>
                <material name="black">
                    <color rgba="0.0 0.0 0.0 1.0"/>
                </material>
            </visual>

            <collision>
                <origin xyz="0 0 0" rpy="0 0 0"/>
                <geometry>
                    <mesh filename="file://$(find skratch_description)/meshes/wheels/kelo_drive_wheel.stl" scale="1 1 1"/>
                </geometry>
            </collision>

            <inertial>
                <origin xyz="0 0 0" rpy="0 0 0"/>
                <mass value="1.56317"/>
                <inertia ixx="0.00101253363" ixy="0.00000000000" ixz="0.00000001020" iyy="0.00157998524" iyz="-0.00000055474" izz="0.00101282739"/>
            </inertial>
            
        </link> 

        <gazebo reference="${name}_link">
            <material>Gazebo/Black</material>
        </gazebo>

        <joint name="${name}_joint" type="continuous">
            <xacro:insert_block name="origin" />
            <axis xyz="0 1 0"/>
            <parent link="${parent}"/>
            <child link="${name}_link" />
        </joint>

    </xacro:macro>  
</robot>
