<?xml version="1.0" ?>
<!-- =================================================================================== -->
<!-- |    This document was autogenerated by xacro from src/kinova_arm_description/description/kinova_arm.urdf.xacro | -->
<!-- |    EDITING THIS FILE BY HAND IS NOT RECOMMENDED                                 | -->
<!-- =================================================================================== -->
<robot name="kinova_arm">
  <gazebo>
    <plugin filename="libgazebo_ros2_control.so" name="arm_ros2_control">
      <parameters>/home/chaitanya/learning/ros_workspace/install/kinova_arm_gazebo/share/kinova_arm_gazebo/config/kinova_arm_controller.yaml</parameters>
    </plugin>
  </gazebo>
  <ros2_control name="kinova_arm" type="system">
    <hardware>
      <!-- By default, set up controllers for simulation. This won't work on real hardware -->
      <plugin>gazebo_ros2_control/GazeboSystem</plugin>
    </hardware>
    <joint name="shoulder_joint">
      <command_interface name="position"/>
      <command_interface name="velocity"/>
      <state_interface name="position">
        <param name="initial_value">0.0</param>
      </state_interface>
      <state_interface name="velocity"/>
    </joint>
    <joint name="half_arm_one_joint">
      <command_interface name="position"/>
      <command_interface name="velocity"/>
      <state_interface name="position">
        <param name="initial_value">-1.0</param>
      </state_interface>
      <state_interface name="velocity"/>
    </joint>
    <joint name="half_arm_two_joint">
      <command_interface name="position"/>
      <command_interface name="velocity"/>
      <state_interface name="position">
        <param name="initial_value">0.0</param>
      </state_interface>
      <state_interface name="velocity"/>
    </joint>
    <joint name="fore_arm_joint">
      <command_interface name="position"/>
      <command_interface name="velocity"/>
      <state_interface name="position">
        <param name="initial_value">1.5</param>
      </state_interface>
      <state_interface name="velocity"/>
    </joint>
    <joint name="spherical_wrist_one_joint">
      <command_interface name="position"/>
      <command_interface name="velocity"/>
      <state_interface name="position">
        <param name="initial_value">0.0</param>
      </state_interface>
      <state_interface name="velocity"/>
    </joint>
    <joint name="spherical_wrist_two_joint">
      <command_interface name="position"/>
      <command_interface name="velocity"/>
      <state_interface name="position">
        <param name="initial_value">1.2</param>
      </state_interface>
      <state_interface name="velocity"/>
    </joint>
    <joint name="camera_joint">
      <command_interface name="position"/>
      <command_interface name="velocity"/>
      <state_interface name="position">
        <param name="initial_value">0.0</param>
      </state_interface>
      <state_interface name="velocity"/>
    </joint>
    <joint name="gripper_left_knuckle_joint">
      <command_interface name="position"/>
      <command_interface name="velocity"/>
      <state_interface name="position">
        <param name="initial_value">0.0</param>
      </state_interface>
      <state_interface name="velocity"/>
    </joint>
  </ros2_control>
  <gazebo reference="kinova_camera">
    <sensor name="arm_camera" type="depth">
      <pose>0.06 0.05 0 1.57 0 1.57</pose>
      <visualize>true</visualize>
      <update_rate>30</update_rate>
      <camera>
        <horizontal_fov>1.134</horizontal_fov>
        <image>
          <width>640</width>
          <height>480</height>
          <format>R8G8B8</format>
        </image>
        <clip>
          <near>0.18</near>
          <far>8.0</far>
        </clip>
      </camera>
      <plugin filename="libgazebo_ros_camera.so" name="camera_controller">
        <frame_name>kinova_camera_optical_frame</frame_name>
      </plugin>
    </sensor>
  </gazebo>
  <gazebo>
    <plugin filename="libgazebo_mimic_joint_plugin.so" name="gripper_right_knuckle_joint">
      <joint>gripper_left_knuckle_joint</joint>
      <mimicJoint>gripper_right_knuckle_joint</mimicJoint>
      <multiplier>-1.0</multiplier>
    </plugin>
    <plugin filename="libgazebo_mimic_joint_plugin.so" name="gripper_left_inner_knuckle_joint">
      <joint>gripper_right_knuckle_joint</joint>
      <mimicJoint>gripper_left_inner_knuckle_joint</mimicJoint>
      <multiplier>-1.0</multiplier>
    </plugin>
    <plugin filename="libgazebo_mimic_joint_plugin.so" name="gripper_right_inner_knuckle_joint">
      <joint>gripper_right_knuckle_joint</joint>
      <mimicJoint>gripper_right_inner_knuckle_joint</mimicJoint>
    </plugin>
    <plugin filename="libgazebo_mimic_joint_plugin.so" name="gripper_left_finger_tip_joint">
      <joint>gripper_right_knuckle_joint</joint>
      <mimicJoint>gripper_left_finger_tip_joint</mimicJoint>
    </plugin>
    <plugin filename="libgazebo_mimic_joint_plugin.so" name="gripper_right_finger_tip_joint">
      <joint>gripper_right_knuckle_joint</joint>
      <mimicJoint>gripper_right_finger_tip_joint</mimicJoint>
      <multiplier>-1.0</multiplier>
    </plugin>
  </gazebo>
  <gazebo reference="gripper_left_finger_tip_link">
    <kp>1000000.0</kp>
    <kd>1.0</kd>
    <mu1>1.0</mu1>
    <mu2>1.0</mu2>
    <minDepth>0.001</minDepth>
  </gazebo>
  <gazebo reference="gripper_right_finger_tip_link">
    <kp>1000000.0</kp>
    <kd>1.0</kd>
    <mu1>1.0</mu1>
    <mu2>1.0</mu2>
    <minDepth>0.001</minDepth>
  </gazebo>
  <link name="kinova_base">
    <inertial>
      <origin rpy="0.0 0.0 0.0" xyz="0.0007117526096760857 0.07634930281943218 0.00010627340345302608"/>
      <mass value="1.697"/>
      <inertia ixx="0.004622" ixy="9E-06" ixz="6E-05" iyy="0.004495" iyz="9E-06" izz="0.002079"/>
    </inertial>
    <visual>
      <origin rpy="0.0 0.0 0.0" xyz="0.0 0.0 0.0"/>
      <geometry>
        <mesh filename="package://kinova_arm_description/meshes/arm/kinova_base.stl" scale="0.001 0.001 0.001"/>
      </geometry>
      <material name="carbon_fiber">
        <color rgba="0.792156862745098 0.819607843137255 0.933333333333333 1"/>
      </material>
    </visual>
    <collision>
      <origin rpy="0.0 0.0 0.0" xyz="0.0 0.0 0.0"/>
      <geometry>
        <mesh filename="package://kinova_arm_description/meshes/arm/kinova_base.stl" scale="0.001 0.001 0.001"/>
      </geometry>
    </collision>
  </link>
  <gazebo reference="kinova_base">
    <material>Gazebo/LightBlue</material>
  </gazebo>
  <link name="kinova_shoulder">
    <inertial>
      <origin rpy="0.0 0.0 0.0" xyz="0.07198810883830421 0.009804160395352531 1.1709966243007998e-08"/>
      <mass value="1.3773"/>
      <inertia ixx="0.00457" ixy="1E-06" ixz="2E-06" iyy="0.004831" iyz="0.000448" izz="0.001409"/>
    </inertial>
    <visual>
      <origin rpy="1.57 0 1.57" xyz="-0.009 0.0 -0.009"/>
      <geometry>
        <mesh filename="package://kinova_arm_description/meshes/arm/kinova_shoulder.stl" scale="0.001 0.001 0.001"/>
      </geometry>
      <material name="carbon_fiber">
        <color rgba="0.792156862745098 0.819607843137255 0.933333333333333 1"/>
      </material>
    </visual>
    <collision>
      <origin rpy="1.57 0 1.57" xyz="-0.009 0.0 -0.009"/>
      <geometry>
        <mesh filename="package://kinova_arm_description/meshes/arm/kinova_shoulder.stl" scale="0.001 0.001 0.001"/>
      </geometry>
    </collision>
  </link>
  <gazebo reference="kinova_shoulder">
    <material>Gazebo/LightBlue</material>
  </gazebo>
  <joint name="shoulder_joint" type="continuous">
    <origin rpy="0 0 0" xyz="0 0.154 0"/>
    <parent link="kinova_base"/>
    <child link="kinova_shoulder"/>
    <axis xyz="0.0 1.0 0.0"/>
  </joint>
  <link name="kinova_half_arm_one">
    <inertial>
      <origin rpy="0.0 0.0 0.0" xyz="0.09866225956007688 0.006787291572545321 2.2830542429196597e-06"/>
      <mass value="1.1636"/>
      <inertia ixx="0.011088" ixy="5E-06" ixz="0" iyy="0.001072" iyz="-0.000691" izz="0.011255"/>
    </inertial>
    <visual>
      <origin rpy="-1.57 0 1.57" xyz="0 0.0 -0.011"/>
      <geometry>
        <mesh filename="package://kinova_arm_description/meshes/arm/kinova_half_arm_one.stl" scale="0.001 0.001 0.001"/>
      </geometry>
      <material name="carbon_fiber">
        <color rgba="0.792156862745098 0.819607843137255 0.933333333333333 1"/>
      </material>
    </visual>
    <collision>
      <origin rpy="-1.57 0 1.57" xyz="0 0.0 -0.011"/>
      <geometry>
        <mesh filename="package://kinova_arm_description/meshes/arm/kinova_half_arm_one.stl" scale="0.001 0.001 0.001"/>
      </geometry>
    </collision>
  </link>
  <gazebo reference="kinova_half_arm_one">
    <material>Gazebo/LightBlue</material>
  </gazebo>
  <joint name="half_arm_one_joint" type="revolute">
    <origin rpy="0 0 0" xyz="0 0.126 0"/>
    <parent link="kinova_shoulder"/>
    <child link="kinova_half_arm_one"/>
    <axis xyz="0.0 0.0 1.0"/>
    <limit effort="1000" lower="-2.249729" upper="2.249729" velocity="1000"/>
  </joint>
  <link name="kinova_half_arm_two">
    <inertial>
      <origin rpy="0.0 0.0 0.0" xyz="0.09866225956007688 0.006787291572545321 2.2830542429196597e-06"/>
      <mass value="1.1636"/>
      <inertia ixx="0.010932" ixy="0" ixz="-7E-06" iyy="0.011127" iyz="0.000606" izz="0.001043"/>
    </inertial>
    <visual>
      <origin rpy="1.57 0 -1.57" xyz="0 0.22 0"/>
      <geometry>
        <mesh filename="package://kinova_arm_description/meshes/arm/kinova_half_arm_two.stl" scale="0.001 0.001 0.001"/>
      </geometry>
      <material name="carbon_fiber">
        <color rgba="0.792156862745098 0.819607843137255 0.933333333333333 1"/>
      </material>
    </visual>
    <collision>
      <origin rpy="1.57 0 -1.57" xyz="0 0.22 0"/>
      <geometry>
        <mesh filename="package://kinova_arm_description/meshes/arm/kinova_half_arm_two.stl" scale="0.001 0.001 0.001"/>
      </geometry>
    </collision>
  </link>
  <gazebo reference="kinova_half_arm_two">
    <material>Gazebo/LightBlue</material>
  </gazebo>
  <joint name="half_arm_two_joint" type="continuous">
    <origin rpy="0 0 0" xyz="0 0.2 -0.011"/>
    <parent link="kinova_half_arm_one"/>
    <child link="kinova_half_arm_two"/>
    <axis xyz="0.0 1.0 0.0"/>
  </joint>
  <link name="kinova_fore_arm">
    <inertial>
      <origin rpy="0.0 0.0 0.0" xyz="0.07607203845617713 0.00824223456213911 -1.8156195599589993e-08"/>
      <mass value="0.9302"/>
      <inertia ixx="0.008147" ixy="-1E-06" ixz="0" iyy="0.000631" iyz="-0.0005" izz="0.008316"/>
    </inertial>
    <visual>
      <origin rpy="-1.57 0 1.57" xyz="0 0 -0.012"/>
      <geometry>
        <mesh filename="package://kinova_arm_description/meshes/arm/kinova_fore_arm.stl" scale="0.001 0.001 0.001"/>
      </geometry>
      <material name="carbon_fiber">
        <color rgba="0.792156862745098 0.819607843137255 0.933333333333333 1"/>
      </material>
    </visual>
    <collision>
      <origin rpy="-1.57 0 1.57" xyz="0 0 -0.012"/>
      <geometry>
        <mesh filename="package://kinova_arm_description/meshes/arm/kinova_fore_arm.stl" scale="0.001 0.001 0.001"/>
      </geometry>
    </collision>
  </link>
  <gazebo reference="kinova_fore_arm">
    <material>Gazebo/LightBlue</material>
  </gazebo>
  <joint name="fore_arm_joint" type="revolute">
    <origin rpy="0 0 0" xyz="0 0.22 0"/>
    <parent link="kinova_half_arm_two"/>
    <child link="kinova_fore_arm"/>
    <axis xyz="0.0 0.0 1.0"/>
    <limit effort="1000" lower="-2.579597" upper="2.579597" velocity="1000"/>
  </joint>
  <link name="kinova_spherical_wrist_one">
    <inertial>
      <origin rpy="0.0 0.0 0.0" xyz="0.060574574716361816 0.009255380929244132 -3.3978512789246475e-09"/>
      <mass value="0.6781"/>
      <inertia ixx="0.001596" ixy="0" ixz="0" iyy="0.001607" iyz="0.000256" izz="0.000399"/>
    </inertial>
    <visual>
      <origin rpy="1.57 0 1.57" xyz="0 0 0"/>
      <geometry>
        <mesh filename="package://kinova_arm_description/meshes/arm/kinova_spherical_wrist_one.stl" scale="0.001 0.001 0.001"/>
      </geometry>
      <material name="carbon_fiber">
        <color rgba="0.792156862745098 0.819607843137255 0.933333333333333 1"/>
      </material>
    </visual>
    <collision>
      <origin rpy="1.57 0 1.57" xyz="0 0 0"/>
      <geometry>
        <mesh filename="package://kinova_arm_description/meshes/arm/kinova_spherical_wrist_one.stl" scale="0.001 0.001 0.001"/>
      </geometry>
    </collision>
  </link>
  <gazebo reference="kinova_spherical_wrist_one">
    <material>Gazebo/LightBlue</material>
  </gazebo>
  <joint name="spherical_wrist_one_joint" type="continuous">
    <origin rpy="0 0 0" xyz="0 0.21 -0.012"/>
    <parent link="kinova_fore_arm"/>
    <child link="kinova_spherical_wrist_one"/>
    <axis xyz="0.0 1.0 0.0"/>
  </joint>
  <link name="kinova_spherical_wrist_two">
    <inertial>
      <origin rpy="0.0 0.0 0.0" xyz="0.060574574716361816 0.009255380929244132 -3.3978512789246475e-09"/>
      <mass value="0.6781"/>
      <inertia ixx="0.001641" ixy="0" ixz="0" iyy="0.00041" iyz="-0.000278" izz="0.001641"/>
    </inertial>
    <visual>
      <origin rpy="1.57 3.14 1.57" xyz="0 0.1035 0"/>
      <geometry>
        <mesh filename="package://kinova_arm_description/meshes/arm/kinova_spherical_wrist_two.stl" scale="0.001 0.001 0.001"/>
      </geometry>
      <material name="carbon_fiber">
        <color rgba="0.792156862745098 0.819607843137255 0.933333333333333 1"/>
      </material>
    </visual>
    <collision>
      <origin rpy="1.57 3.14 1.57" xyz="0 0.1035 0"/>
      <geometry>
        <mesh filename="package://kinova_arm_description/meshes/arm/kinova_spherical_wrist_two.stl" scale="0.001 0.001 0.001"/>
      </geometry>
    </collision>
  </link>
  <gazebo reference="kinova_spherical_wrist_two">
    <material>Gazebo/LightBlue</material>
  </gazebo>
  <joint name="spherical_wrist_two_joint" type="revolute">
    <origin rpy="0 0 0" xyz="0 0.1035 0"/>
    <parent link="kinova_spherical_wrist_one"/>
    <child link="kinova_spherical_wrist_two"/>
    <axis xyz="0.0 0.0 1.0"/>
    <limit effort="1000" lower="-2.099631" upper="2.099631" velocity="1000"/>
  </joint>
  <link name="kinova_camera">
    <inertial>
      <origin rpy="0.0 0.0 0.0" xyz="0.060574574716361816 0.009255380929244132 -3.3978512789246475e-09"/>
      <mass value="0.5006"/>
      <inertia ixx="0.000587" ixy="3E-06" ixz="3E-06" iyy="0.000369" iyz="0.000118" izz="0.000609"/>
    </inertial>
    <visual>
      <origin rpy="-1.57 -1.57 0" xyz="0 0 0"/>
      <geometry>
        <mesh filename="package://kinova_arm_description/meshes/arm/kinova_camera.stl" scale="0.001 0.001 0.001"/>
      </geometry>
      <material name="carbon_fiber">
        <color rgba="0.792156862745098 0.819607843137255 0.933333333333333 1"/>
      </material>
    </visual>
    <collision>
      <origin rpy="-1.57 -1.57 0" xyz="0 0 0"/>
      <geometry>
        <mesh filename="package://kinova_arm_description/meshes/arm/kinova_camera.stl" scale="0.001 0.001 0.001"/>
      </geometry>
    </collision>
  </link>
  <gazebo reference="kinova_camera">
    <material>Gazebo/LightBlue</material>
  </gazebo>
  <joint name="camera_joint" type="continuous">
    <origin rpy="0 0 0" xyz="0 0.11 0"/>
    <parent link="kinova_spherical_wrist_two"/>
    <child link="kinova_camera"/>
    <axis xyz="0.0 1.0 0.0"/>
  </joint>
  <link name="gripper_base_link">
    <visual>
      <geometry>
        <mesh filename="package://kinova_arm_description/meshes/robotiq_gripper/visual/robotiq_base.dae"/>
      </geometry>
    </visual>
    <collision>
      <geometry>
        <mesh filename="package://kinova_arm_description/meshes/robotiq_gripper/collision/robotiq_base.stl"/>
      </geometry>
    </collision>
    <inertial>
      <origin rpy="0 0 0" xyz="0.0 2.274e-05 0.03232288"/>
      <mass value="6.6320197e-01"/>
      <inertia ixx="5.1617816e-04" ixy="2.936e-8" ixz="0.0" iyy="5.8802208e-04" iyz="-3.2296e-7" izz="3.9462776e-04"/>
    </inertial>
  </link>
  <link name="gripper_left_knuckle_link">
    <visual>
      <geometry>
        <mesh filename="package://kinova_arm_description/meshes/robotiq_gripper/visual/left_knuckle.dae"/>
      </geometry>
    </visual>
    <collision>
      <geometry>
        <mesh filename="package://kinova_arm_description/meshes/robotiq_gripper/collision/left_knuckle.stl"/>
      </geometry>
    </collision>
    <inertial>
      <origin rpy="0 0 0" xyz="0.01213197 0.0002 -0.00058647"/>
      <mass value="1.384773208e-02"/>
      <inertia ixx="3.5232e-7" ixy="0.0" ixz="1.1744e-7" iyy="2.31944e-6" iyz="0" izz="2.23136e-6"/>
    </inertial>
  </link>
  <link name="gripper_right_knuckle_link">
    <visual>
      <geometry>
        <mesh filename="package://kinova_arm_description/meshes/robotiq_gripper/visual/right_knuckle.dae"/>
      </geometry>
    </visual>
    <collision>
      <geometry>
        <mesh filename="package://kinova_arm_description/meshes/robotiq_gripper/collision/right_knuckle.stl"/>
      </geometry>
    </collision>
    <inertial>
      <origin rpy="0 0 0" xyz="-0.01213197 0.0002 -0.00058647"/>
      <mass value="1.384773208e-02"/>
      <inertia ixx="3.5232e-7" ixy="0.0" ixz="-1.1744e-7" iyy="2.31944e-6" iyz="0.0" izz="2.23136e-6"/>
    </inertial>
  </link>
  <link name="gripper_left_finger_link">
    <visual>
      <geometry>
        <mesh filename="package://kinova_arm_description/meshes/robotiq_gripper/visual/left_finger.dae"/>
      </geometry>
    </visual>
    <collision>
      <geometry>
        <mesh filename="package://kinova_arm_description/meshes/robotiq_gripper/collision/left_finger.stl"/>
      </geometry>
    </collision>
    <inertial>
      <origin rpy="0 0 0" xyz="0.00346899 -0.00079447 0.01867121"/>
      <mass value="4.260376752e-02"/>
      <inertia ixx="1.385792000000000e-05" ixy="0.0" ixz="-2.17264e-06" iyy="1.183208e-05" iyz="0.0" izz="5.19672e-06"/>
    </inertial>
  </link>
  <link name="gripper_right_finger_link">
    <visual>
      <geometry>
        <mesh filename="package://kinova_arm_description/meshes/robotiq_gripper/visual/right_finger.dae"/>
      </geometry>
    </visual>
    <collision>
      <geometry>
        <mesh filename="package://kinova_arm_description/meshes/robotiq_gripper/collision/right_finger.stl"/>
      </geometry>
    </collision>
    <inertial>
      <origin rpy="0 0 0" xyz="-0.00346899 -5.53e-06 0.01867121"/>
      <mass value="4.260376752000000e-02"/>
      <inertia ixx="1.385792e-05" ixy="0.0" ixz="2.17264e-06" iyy="1.183208e-05" iyz="0.0" izz="5.19672e-06"/>
    </inertial>
  </link>
  <link name="gripper_left_inner_knuckle_link">
    <visual>
      <geometry>
        <mesh filename="package://kinova_arm_description/meshes/robotiq_gripper/visual/left_inner_knuckle.dae"/>
      </geometry>
    </visual>
    <collision>
      <geometry>
        <mesh filename="package://kinova_arm_description/meshes/robotiq_gripper/collision/left_inner_knuckle.stl"/>
      </geometry>
    </collision>
    <inertial>
      <origin rpy="0 0 0" xyz="0.01897699 0.00015001 0.02247101"/>
      <mass value="2.969376448e-02"/>
      <inertia ixx="9.57136e-06" ixy="0.0" ixz="-3.93424e-06" iyy="8.69056e-06" iyz="0.0" izz="8.19144e-06"/>
    </inertial>
  </link>
  <link name="gripper_right_inner_knuckle_link">
    <visual>
      <geometry>
        <mesh filename="package://kinova_arm_description/meshes/robotiq_gripper/visual/right_inner_knuckle.dae"/>
      </geometry>
    </visual>
    <collision>
      <geometry>
        <mesh filename="package://kinova_arm_description/meshes/robotiq_gripper/collision/right_inner_knuckle.stl"/>
      </geometry>
    </collision>
    <inertial>
      <origin rpy="0 0 0" xyz="-0.01926824 5.001e-05 0.02222178"/>
      <mass value="2.969376448e-02"/>
      <inertia ixx="9.42456e-06" ixy="0.0" ixz="3.9636e-06" iyy="8.69056e-06" iyz="0.0" izz="8.33824e-06"/>
    </inertial>
  </link>
  <link name="gripper_left_finger_tip_link">
    <contact>
      <friction_anchor/>
      <stiffness value="30000.0"/>
      <damping value="1000.0"/>
      <spinning_friction value="0.1"/>
      <lateral_friction value="1.0"/>
    </contact>
    <visual>
      <geometry>
        <mesh filename="package://kinova_arm_description/meshes/robotiq_gripper/visual/left_finger_tip.dae"/>
      </geometry>
    </visual>
    <collision>
      <geometry>
        <mesh filename="package://kinova_arm_description/meshes/robotiq_gripper/collision/left_finger_tip.stl"/>
      </geometry>
    </collision>
    <inertial>
      <origin rpy="0 0 0" xyz="-0.01456706 -0.0008 0.01649701"/>
      <mass value="4.268588744e-02"/>
      <inertia ixx="1.048152e-05" ixy="0.0" ixz="3.5232e-6" iyy="1.197888e-05" iyz="0.0" izz="4.22784e-06"/>
    </inertial>
  </link>
  <link name="gripper_right_finger_tip_link">
    <contact>
      <friction_anchor/>
      <stiffness value="30000.0"/>
      <damping value="1000.0"/>
      <spinning_friction value="0.1"/>
      <lateral_friction value="1.0"/>
    </contact>
    <visual>
      <geometry>
        <mesh filename="package://kinova_arm_description/meshes/robotiq_gripper/visual/right_finger_tip.dae"/>
      </geometry>
    </visual>
    <collision>
      <geometry>
        <mesh filename="package://kinova_arm_description/meshes/robotiq_gripper/collision/right_finger_tip.stl"/>
      </geometry>
    </collision>
    <inertial>
      <origin rpy="0 0 0" xyz="0.01456706 5e-05 0.01649701"/>
      <mass value="4.268588744e-02"/>
      <inertia ixx="1.048152e-05" ixy="0.0" ixz="-3.5232e-06" iyy="1.197888e-05" iyz="0.0" izz="4.22784e-06"/>
    </inertial>
  </link>
  <joint name="gripper_left_knuckle_joint" type="revolute">
    <parent link="gripper_base_link"/>
    <child link="gripper_left_knuckle_link"/>
    <axis xyz="0 -1 0"/>
    <origin rpy="0 0 0" xyz="0.03060114 0.0 0.05490452"/>
    <limit effort="50" lower="0.0" upper="0.8" velocity="0.5"/>
  </joint>
  <joint name="gripper_right_knuckle_joint" type="revolute">
    <parent link="gripper_base_link"/>
    <child link="gripper_right_knuckle_link"/>
    <axis xyz="0 -1 0"/>
    <origin rpy="0 0 0" xyz="-0.03060114 0.0 0.05490452"/>
    <limit effort="50" lower="-0.8" upper="0.0" velocity="0.5"/>
    <mimic joint="gripper_left_knuckle_joint" multiplier="-1"/>
  </joint>
  <joint name="gripper_left_finger_joint" type="fixed">
    <parent link="gripper_left_knuckle_link"/>
    <child link="gripper_left_finger_link"/>
    <origin rpy="0 0 0" xyz="0.03152616 0.0 -0.00376347"/>
  </joint>
  <joint name="gripper_right_finger_joint" type="fixed">
    <parent link="gripper_right_knuckle_link"/>
    <child link="gripper_right_finger_link"/>
    <origin rpy="0 0 0" xyz="-0.03152616 0.0 -0.00376347"/>
  </joint>
  <joint name="gripper_left_inner_knuckle_joint" type="continuous">
    <parent link="gripper_base_link"/>
    <child link="gripper_left_inner_knuckle_link"/>
    <axis xyz="0 -1 0"/>
    <origin rpy="0 0 0" xyz="0.0127 0.0 0.06142"/>
    <mimic joint="gripper_left_knuckle_joint"/>
  </joint>
  <joint name="gripper_right_inner_knuckle_joint" type="continuous">
    <parent link="gripper_base_link"/>
    <child link="gripper_right_inner_knuckle_link"/>
    <axis xyz="0 -1 0"/>
    <origin rpy="0 0 0" xyz="-0.0127 0.0 0.06142"/>
    <mimic joint="gripper_left_knuckle_joint" multiplier="-1"/>
  </joint>
  <joint name="gripper_left_finger_tip_joint" type="continuous">
    <parent link="gripper_left_finger_link"/>
    <child link="gripper_left_finger_tip_link"/>
    <axis xyz="0 -1 0"/>
    <origin rpy="0 0 0" xyz="0.00563134 0.0 0.04718515"/>
    <mimic joint="gripper_left_knuckle_joint" multiplier="-1"/>
  </joint>
  <joint name="gripper_right_finger_tip_joint" type="continuous">
    <parent link="gripper_right_finger_link"/>
    <child link="gripper_right_finger_tip_link"/>
    <axis xyz="0 -1 0"/>
    <origin rpy="0 0 0" xyz="-0.00563134 0.0 0.04718515"/>
    <mimic joint="gripper_left_knuckle_joint"/>
  </joint>
  <joint name="gripper_joint" type="fixed">
    <origin rpy="1.57 1.57 -3.14" xyz="0 0.06 0"/>
    <parent link="kinova_camera"/>
    <child link="gripper_base_link"/>
  </joint>
  <link name="kinova_camera_optical_frame"/>
  <joint name="kinova_camera_optical_joint" type="fixed">
    <origin rpy="0 1.57 1.57" xyz="0 0 0"/>
    <parent link="kinova_camera"/>
    <child link="kinova_camera_optical_frame"/>
  </joint>
  <joint name="arm_base_joint" type="fixed">
    <origin rpy="1.57 0.0 3.14" xyz="0.0 0.0 0.0"/>
    <parent link="arm_base_link"/>
    <child link="kinova_base"/>
  </joint>
  <link name="arm_base_link">
    <inertial>
      <mass value="50.0"/>
      <origin rpy="0 0 0" xyz="0 0 0"/>
      <inertia ixx="5.0" ixy="0" ixz="0" iyy="5.0" iyz="0" izz="5.0"/>
    </inertial>
  </link>
</robot>
